Workbook

Sheet Dashboard
A1: HERO — DASHBOARD PROYEK
A2: Seluruh angka dihitung otomatis dari sheet Tracker dan Milestone. Jangan diketik manual. | H2: Diperbarui: | I2: 46279
A4: Fase | B4: Milestone | C4: Periode | D4: Task | E4: To Do | F4: In Progress | G4: In Review | H4: Done | I4: Blocked | J4: % Selesai | K4: Progres | L4: SP Total | M4: SP Selesai | N4: Indikator
A5: Fase 0 | B5: Inception & Setup | C5: 31 Aug – 13 Sep | D5: =COUNTIF(Tracker!$B:$B,A5) | E5: =COUNTIFS(Tracker!$B:$B,A5,Tracker!$L:$L,"To Do") | F5: =COUNTIFS(Tracker!$B:$B,A5,Tracker!$L:$L,"In Progress") | G5: =COUNTIFS(Tracker!$B:$B,A5,Tracker!$L:$L,"In Review / Testing") | H5: =COUNTIFS(Tracker!$B:$B,A5,Tracker!$L:$L,"Done") | I5: =COUNTIFS(Tracker!$B:$B,A5,Tracker!$L:$L,"Blocked") | J5: =IFERROR(H5/D5,0) | K5: =REPT("█",ROUND(J5*20,0))&REPT("░",20-ROUND(J5*20,0)) | L5: =SUMIF(Tracker!$B:$B,A5,Tracker!$J:$J) | M5: =SUMIFS(Tracker!$J:$J,Tracker!$B:$B,A5,Tracker!$L:$L,"Done") | N5: =COUNTIF(Milestone!$E$5:$E$7,"Tercapai")&" / "&ROWS(Milestone!$E$5:$E$7)
A6: Fase 1 | B6: MVP Scraping & Ingest | C6: 14 Sep – 11 Oct | D6: =COUNTIF(Tracker!$B:$B,A6) | E6: =COUNTIFS(Tracker!$B:$B,A6,Tracker!$L:$L,"To Do") | F6: =COUNTIFS(Tracker!$B:$B,A6,Tracker!$L:$L,"In Progress") | G6: =COUNTIFS(Tracker!$B:$B,A6,Tracker!$L:$L,"In Review / Testing") | H6: =COUNTIFS(Tracker!$B:$B,A6,Tracker!$L:$L,"Done") | I6: =COUNTIFS(Tracker!$B:$B,A6,Tracker!$L:$L,"Blocked") | J6: =IFERROR(H6/D6,0) | K6: =REPT("█",ROUND(J6*20,0))&REPT("░",20-ROUND(J6*20,0)) | L6: =SUMIF(Tracker!$B:$B,A6,Tracker!$J:$J) | M6: =SUMIFS(Tracker!$J:$J,Tracker!$B:$B,A6,Tracker!$L:$L,"Done") | N6: =COUNTIF(Milestone!$E$8:$E$12,"Tercapai")&" / "&ROWS(Milestone!$E$8:$E$12)
A7: Fase 2 | B7: MVP Analisa & Summary | C7: 12 Oct – 08 Nov | D7: =COUNTIF(Tracker!$B:$B,A7) | E7: =COUNTIFS(Tracker!$B:$B,A7,Tracker!$L:$L,"To Do") | F7: =COUNTIFS(Tracker!$B:$B,A7,Tracker!$L:$L,"In Progress") | G7: =COUNTIFS(Tracker!$B:$B,A7,Tracker!$L:$L,"In Review / Testing") | H7: =COUNTIFS(Tracker!$B:$B,A7,Tracker!$L:$L,"Done") | I7: =COUNTIFS(Tracker!$B:$B,A7,Tracker!$L:$L,"Blocked") | J7: =IFERROR(H7/D7,0) | K7: =REPT("█",ROUND(J7*20,0))&REPT("░",20-ROUND(J7*20,0)) | L7: =SUMIF(Tracker!$B:$B,A7,Tracker!$J:$J) | M7: =SUMIFS(Tracker!$J:$J,Tracker!$B:$B,A7,Tracker!$L:$L,"Done") | N7: =COUNTIF(Milestone!$E$13:$E$15,"Tercapai")&" / "&ROWS(Milestone!$E$13:$E$15)
A8: Fase 3 | B8: MVP Harmonisasi | C8: 09 Nov – 29 Nov | D8: =COUNTIF(Tracker!$B:$B,A8) | E8: =COUNTIFS(Tracker!$B:$B,A8,Tracker!$L:$L,"To Do") | F8: =COUNTIFS(Tracker!$B:$B,A8,Tracker!$L:$L,"In Progress") | G8: =COUNTIFS(Tracker!$B:$B,A8,Tracker!$L:$L,"In Review / Testing") | H8: =COUNTIFS(Tracker!$B:$B,A8,Tracker!$L:$L,"Done") | I8: =COUNTIFS(Tracker!$B:$B,A8,Tracker!$L:$L,"Blocked") | J8: =IFERROR(H8/D8,0) | K8: =REPT("█",ROUND(J8*20,0))&REPT("░",20-ROUND(J8*20,0)) | L8: =SUMIF(Tracker!$B:$B,A8,Tracker!$J:$J) | M8: =SUMIFS(Tracker!$J:$J,Tracker!$B:$B,A8,Tracker!$L:$L,"Done") | N8: =COUNTIF(Milestone!$E$16:$E$17,"Tercapai")&" / "&ROWS(Milestone!$E$16:$E$17)
A9: Fase 4 | B9: MVP Tanggapan PoV | C9: 30 Nov – 13 Dec | D9: =COUNTIF(Tracker!$B:$B,A9) | E9: =COUNTIFS(Tracker!$B:$B,A9,Tracker!$L:$L,"To Do") | F9: =COUNTIFS(Tracker!$B:$B,A9,Tracker!$L:$L,"In Progress") | G9: =COUNTIFS(Tracker!$B:$B,A9,Tracker!$L:$L,"In Review / Testing") | H9: =COUNTIFS(Tracker!$B:$B,A9,Tracker!$L:$L,"Done") | I9: =COUNTIFS(Tracker!$B:$B,A9,Tracker!$L:$L,"Blocked") | J9: =IFERROR(H9/D9,0) | K9: =REPT("█",ROUND(J9*20,0))&REPT("░",20-ROUND(J9*20,0)) | L9: =SUMIF(Tracker!$B:$B,A9,Tracker!$J:$J) | M9: =SUMIFS(Tracker!$J:$J,Tracker!$B:$B,A9,Tracker!$L:$L,"Done") | N9: =COUNTIF(Milestone!$E$18:$E$19,"Tercapai")&" / "&ROWS(Milestone!$E$18:$E$19)
A10: Fase 5 | B10: Stabilisasi & UAT | C10: 14 Dec – 24 Dec | D10: =COUNTIF(Tracker!$B:$B,A10) | E10: =COUNTIFS(Tracker!$B:$B,A10,Tracker!$L:$L,"To Do") | F10: =COUNTIFS(Tracker!$B:$B,A10,Tracker!$L:$L,"In Progress") | G10: =COUNTIFS(Tracker!$B:$B,A10,Tracker!$L:$L,"In Review / Testing") | H10: =COUNTIFS(Tracker!$B:$B,A10,Tracker!$L:$L,"Done") | I10: =COUNTIFS(Tracker!$B:$B,A10,Tracker!$L:$L,"Blocked") | J10: =IFERROR(H10/D10,0) | K10: =REPT("█",ROUND(J10*20,0))&REPT("░",20-ROUND(J10*20,0)) | L10: =SUMIF(Tracker!$B:$B,A10,Tracker!$J:$J) | M10: =SUMIFS(Tracker!$J:$J,Tracker!$B:$B,A10,Tracker!$L:$L,"Done") | N10: =COUNTIF(Milestone!$E$20:$E$22,"Tercapai")&" / "&ROWS(Milestone!$E$20:$E$22)
A11: TOTAL | D11: =SUM(D5:D10) | E11: =SUM(E5:E10) | F11: =SUM(F5:F10) | G11: =SUM(G5:G10) | H11: =SUM(H5:H10) | I11: =SUM(I5:I10) | J11: =IFERROR(H11/D11,0) | K11: =REPT("█",ROUND(J11*20,0))&REPT("░",20-ROUND(J11*20,0)) | L11: =SUM(L5:L10) | M11: =SUM(M5:M10) | N11: =COUNTIF(Milestone!$E:$E,"Tercapai")&" / "&COUNTA(Milestone!$D$5:$D$22)
A14: BEBAN PER PIC
A15: PIC | B15: Total | C15: To Do | D15: In Progress | E15: In Review | F15: Done | G15: Blocked | H15: SP Aktif
A16: Zaky | B16: =COUNTIF(Tracker!$H:$H,A16) | C16: =COUNTIFS(Tracker!$H:$H,A16,Tracker!$L:$L,"To Do") | D16: =COUNTIFS(Tracker!$H:$H,A16,Tracker!$L:$L,"In Progress") | E16: =COUNTIFS(Tracker!$H:$H,A16,Tracker!$L:$L,"In Review / Testing") | F16: =COUNTIFS(Tracker!$H:$H,A16,Tracker!$L:$L,"Done") | G16: =COUNTIFS(Tracker!$H:$H,A16,Tracker!$L:$L,"Blocked") | H16: =SUMIFS(Tracker!$J:$J,Tracker!$H:$H,A16,Tracker!$L:$L,"<>Done")
A17: Rafli | B17: =COUNTIF(Tracker!$H:$H,A17) | C17: =COUNTIFS(Tracker!$H:$H,A17,Tracker!$L:$L,"To Do") | D17: =COUNTIFS(Tracker!$H:$H,A17,Tracker!$L:$L,"In Progress") | E17: =COUNTIFS(Tracker!$H:$H,A17,Tracker!$L:$L,"In Review / Testing") | F17: =COUNTIFS(Tracker!$H:$H,A17,Tracker!$L:$L,"Done") | G17: =COUNTIFS(Tracker!$H:$H,A17,Tracker!$L:$L,"Blocked") | H17: =SUMIFS(Tracker!$J:$J,Tracker!$H:$H,A17,Tracker!$L:$L,"<>Done")
A18: Ikhwan | B18: =COUNTIF(Tracker!$H:$H,A18) | C18: =COUNTIFS(Tracker!$H:$H,A18,Tracker!$L:$L,"To Do") | D18: =COUNTIFS(Tracker!$H:$H,A18,Tracker!$L:$L,"In Progress") | E18: =COUNTIFS(Tracker!$H:$H,A18,Tracker!$L:$L,"In Review / Testing") | F18: =COUNTIFS(Tracker!$H:$H,A18,Tracker!$L:$L,"Done") | G18: =COUNTIFS(Tracker!$H:$H,A18,Tracker!$L:$L,"Blocked") | H18: =SUMIFS(Tracker!$J:$J,Tracker!$H:$H,A18,Tracker!$L:$L,"<>Done")
A19: Fathir | B19: =COUNTIF(Tracker!$H:$H,A19) | C19: =COUNTIFS(Tracker!$H:$H,A19,Tracker!$L:$L,"To Do") | D19: =COUNTIFS(Tracker!$H:$H,A19,Tracker!$L:$L,"In Progress") | E19: =COUNTIFS(Tracker!$H:$H,A19,Tracker!$L:$L,"In Review / Testing") | F19: =COUNTIFS(Tracker!$H:$H,A19,Tracker!$L:$L,"Done") | G19: =COUNTIFS(Tracker!$H:$H,A19,Tracker!$L:$L,"Blocked") | H19: =SUMIFS(Tracker!$J:$J,Tracker!$H:$H,A19,Tracker!$L:$L,"<>Done")
A20: Hamdan | B20: =COUNTIF(Tracker!$H:$H,A20) | C20: =COUNTIFS(Tracker!$H:$H,A20,Tracker!$L:$L,"To Do") | D20: =COUNTIFS(Tracker!$H:$H,A20,Tracker!$L:$L,"In Progress") | E20: =COUNTIFS(Tracker!$H:$H,A20,Tracker!$L:$L,"In Review / Testing") | F20: =COUNTIFS(Tracker!$H:$H,A20,Tracker!$L:$L,"Done") | G20: =COUNTIFS(Tracker!$H:$H,A20,Tracker!$L:$L,"Blocked") | H20: =SUMIFS(Tracker!$J:$J,Tracker!$H:$H,A20,Tracker!$L:$L,"<>Done")
A23: MENUNGGU MITRA
A24: Jumlah | B24: Keterangan
A25: =COUNTIF(Tracker!$F:$F,"Blocker Mitra") | B25: Item bertipe "Blocker Mitra" di Tracker — tagih pada rapat mingguan
A28: LEGENDA STATUS
A29: To Do | B29: Belum dimulai
A30: In Progress | B30: Sedang dikerjakan
A31: In Review / Testing | B31: Menunggu review atau pengujian
A32: Done | B32: Selesai & memenuhi Definition of Done
A33: Blocked | B33: Terhenti menunggu pihak lain — lihat kolom Blocker / Remarks

Sheet Tracker
A1: HERO — PAPAN PROYEK
A2: Satu baris per task. Kolom Milestone dan Tenggat terisi otomatis dari Fase dan Sprint. Kolom lain bebas diubah lewat dropdown.
A4: No | B4: Fase | C4: Milestone | D4: ID | E4: Task | F4: Tipe | G4: Peran | H4: PIC | I4: Sprint | J4: SP | K4: Prioritas | L4: Status | M4: Tenggat | N4: GitHub # | O4: Blocker / Remarks
A5: 1 | B5: Fase 0 | C5: =IFERROR(VLOOKUP(B5,Referensi!$A$5:$B$10,2,FALSE),"") | D5: US-11 | E5: Lingkungan staging & CI siap | F5: Chore | G5: Infra/QA | H5: Hamdan | I5: S0 | J5: 4 | K5: Must | L5: In Progress | M5: =IFERROR(VLOOKUP(I5,Referensi!$F$5:$G$13,2,FALSE),"") | O5: Belum ada bukti CI berjalan; masuk carry-over
A6: 2 | B6: Fase 0 | C6: =IFERROR(VLOOKUP(B6,Referensi!$A$5:$B$10,2,FALSE),"") | D6: AI-T10 | E6: Format laporan rapat mingguan | F6: Chore | G6: PM/BA | H6: Zaky | I6: S0 | J6: 2 | K6: Must | L6: In Progress | M6: =IFERROR(VLOOKUP(I6,Referensi!$F$5:$G$13,2,FALSE),"") | N6: 23 | O6: Carry-over dari Fase 0
A7: 3 | B7: Fase 0 | C7: =IFERROR(VLOOKUP(B7,Referensi!$A$5:$B$10,2,FALSE),"") | D7: OI-04 | E7: Penandatanganan NDA seluruh anggota | F7: Blocker Mitra | G7: PM/BA | H7: Zaky | I7: S0 | K7: Must | L7: Blocked | M7: =IFERROR(VLOOKUP(I7,Referensi!$F$5:$G$13,2,FALSE),"") | N7: 25 | O7: Memblokir akses OneDrive
A8: 4 | B8: Fase 0 | C8: =IFERROR(VLOOKUP(B8,Referensi!$A$5:$B$10,2,FALSE),"") | D8: F0-3 | E8: Struktur folder knowledge base awal (skeleton) | F8: Chore | G8: Backend | H8: Rafli | I8: S1 | J8: 3 | K8: Must | L8: To Do | M8: =IFERROR(VLOOKUP(I8,Referensi!$F$5:$G$13,2,FALSE),"") | N8: 38 | O8: Indikator Fase 0 yang terlewat, dibawa ke Fase 1
A9: 5 | B9: Fase 0 | C9: =IFERROR(VLOOKUP(B9,Referensi!$A$5:$B$10,2,FALSE),"") | D9: F0-DOC | E9: Dokumen requirement & arsitektur disetujui stakeholder | F9: Chore | G9: PM/BA | H9: Zaky | I9: S0 | K9: Must | L9: In Review / Testing | M9: =IFERROR(VLOOKUP(I9,Referensi!$F$5:$G$13,2,FALSE),"") | O9: 17 dokumen tersusun; persetujuan mitra belum tercatat
A10: 6 | B10: Fase 1 | C10: =IFERROR(VLOOKUP(B10,Referensi!$A$5:$B$10,2,FALSE),"") | D10: US-02 | E10: Login pengguna | F10: User Story | G10: Backend | H10: Rafli | I10: S1 | J10: 3 | K10: Must | L10: To Do | M10: =IFERROR(VLOOKUP(I10,Referensi!$F$5:$G$13,2,FALSE),"") | N10: 1
A11: 7 | B11: Fase 1 | C11: =IFERROR(VLOOKUP(B11,Referensi!$A$5:$B$10,2,FALSE),"") | D11: US-12 | E11: Kelola daftar situs sumber | F11: User Story | G11: Backend | H11: Rafli | I11: S1 | J11: 5 | K11: Must | L11: To Do | M11: =IFERROR(VLOOKUP(I11,Referensi!$F$5:$G$13,2,FALSE),"") | N11: 2
A12: 8 | B12: Fase 1 | C12: =IFERROR(VLOOKUP(B12,Referensi!$A$5:$B$10,2,FALSE),"") | D12: US-13 | E12: Mesin scraping & pengunduhan PDF | F12: User Story | G12: Data/ML | H12: Fathir | I12: S1 | J12: 8 | K12: Must | L12: In Progress | M12: =IFERROR(VLOOKUP(I12,Referensi!$F$5:$G$13,2,FALSE),"") | N12: 3 | O12: Baseline scraper sudah ada. Fathir belum masuk org GitHub
A13: 9 | B13: Fase 1 | C13: =IFERROR(VLOOKUP(B13,Referensi!$A$5:$B$10,2,FALSE),"") | D13: US-13a | E13: Kontrol kedalaman crawling per sumber | F13: User Story | G13: Data/ML | H13: Fathir | I13: S1 | J13: 5 | K13: Must | L13: In Progress | M13: =IFERROR(VLOOKUP(I13,Referensi!$F$5:$G$13,2,FALSE),"") | N13: 4 | O13: Sedang ke kedalaman > 1; kedalaman 1 harus stabil dulu
A14: 10 | B14: Fase 1 | C14: =IFERROR(VLOOKUP(B14,Referensi!$A$5:$B$10,2,FALSE),"") | D14: US-14 | E14: Ringkasan hasil job scraping | F14: User Story | G14: Backend | H14: Rafli | I14: S1 | J14: 3 | K14: Must | L14: To Do | M14: =IFERROR(VLOOKUP(I14,Referensi!$F$5:$G$13,2,FALSE),"") | N14: 5
A15: 11 | B15: Fase 1 | C15: =IFERROR(VLOOKUP(B15,Referensi!$A$5:$B$10,2,FALSE),"") | D15: US-15 | E15: Unggah dokumen manual | F15: User Story | G15: Backend | H15: Rafli | I15: S1 | J15: 5 | K15: Must | L15: To Do | M15: =IFERROR(VLOOKUP(I15,Referensi!$F$5:$G$13,2,FALSE),"") | N15: 6
A16: 12 | B16: Fase 1 | C16: =IFERROR(VLOOKUP(B16,Referensi!$A$5:$B$10,2,FALSE),"") | D16: US-15a | E16: Pilih tipe dokumen: draft kajian / eksisting | F16: User Story | G16: Backend | H16: Rafli | I16: S1 | J16: 3 | K16: Must | L16: To Do | M16: =IFERROR(VLOOKUP(I16,Referensi!$F$5:$G$13,2,FALSE),"") | N16: 7 | O16: Frontend pendukung untuk elemen pilihan
A17: 13 | B17: Fase 1 | C17: =IFERROR(VLOOKUP(B17,Referensi!$A$5:$B$10,2,FALSE),"") | D17: US-18 | E17: Tolak berkas non-PDF | F17: User Story | G17: Backend | H17: Rafli | I17: S1 | J17: 3 | K17: Must | L17: To Do | M17: =IFERROR(VLOOKUP(I17,Referensi!$F$5:$G$13,2,FALSE),"") | N17: 8
A18: 14 | B18: Fase 1 | C18: =IFERROR(VLOOKUP(B18,Referensi!$A$5:$B$10,2,FALSE),"") | D18: US-19 | E18: Deteksi duplikat (hash + ukuran berkas) | F18: User Story | G18: Backend | H18: Rafli | I18: S1 | J18: 5 | K18: Must | L18: To Do | M18: =IFERROR(VLOOKUP(I18,Referensi!$F$5:$G$13,2,FALSE),"") | N18: 9
A19: 15 | B19: Fase 1 | C19: =IFERROR(VLOOKUP(B19,Referensi!$A$5:$B$10,2,FALSE),"") | D19: US-26 | E19: Simpan dokumen + metadata + teks | F19: User Story | G19: Backend | H19: Rafli | I19: S1 | J19: 5 | K19: Must | L19: To Do | M19: =IFERROR(VLOOKUP(I19,Referensi!$F$5:$G$13,2,FALSE),"") | N19: 10
A20: 16 | B20: Fase 1 | C20: =IFERROR(VLOOKUP(B20,Referensi!$A$5:$B$10,2,FALSE),"") | D20: AI-T3 | E20: Mockup Figma Fase 1 | F20: Chore | G20: Frontend | H20: Ikhwan | I20: S1 | J20: 5 | K20: Must | L20: In Progress | M20: =IFERROR(VLOOKUP(I20,Referensi!$F$5:$G$13,2,FALSE),"") | N20: 21 | O20: 3 layar sudah: Dashboard, KB, Ingest. S-04 Antrian Kegagalan belum
A21: 17 | B21: Fase 1 | C21: =IFERROR(VLOOKUP(B21,Referensi!$A$5:$B$10,2,FALSE),"") | D21: AI-T7 | E21: Hosting untuk uji coba mitra 8 Okt | F21: Chore | G21: Infra/QA | H21: Hamdan | I21: S1 | J21: 8 | K21: Must | L21: To Do | M21: =IFERROR(VLOOKUP(I21,Referensi!$F$5:$G$13,2,FALSE),"") | N21: 22 | O21: Menunggu keputusan ADR-11 di rapat mingguan
A22: 18 | B22: Fase 1 | C22: =IFERROR(VLOOKUP(B22,Referensi!$A$5:$B$10,2,FALSE),"") | D22: AI-M1 | E22: Alamat situs sumber ketiga | F22: Blocker Mitra | G22: Mitra | H22: Faris (DPEA) | I22: S1 | K22: Must | L22: Blocked | M22: =IFERROR(VLOOKUP(I22,Referensi!$F$5:$G$13,2,FALSE),"") | N22: 24 | O22: Memblokir indikator ≥ 3 situs
A23: 19 | B23: Fase 1 | C23: =IFERROR(VLOOKUP(B23,Referensi!$A$5:$B$10,2,FALSE),"") | D23: US-20 | E23: Ekstraksi metadata dasar | F23: User Story | G23: Data/ML | H23: Fathir | I23: S2 | J23: 8 | K23: Must | L23: To Do | M23: =IFERROR(VLOOKUP(I23,Referensi!$F$5:$G$13,2,FALSE),"") | N23: 11
A24: 20 | B24: Fase 1 | C24: =IFERROR(VLOOKUP(B24,Referensi!$A$5:$B$10,2,FALSE),"") | D24: US-20a | E24: OCR halaman 1 & penamaan berkas baku | F24: User Story | G24: Data/ML | H24: Fathir | I24: S2 | J24: 5 | K24: Must | L24: To Do | M24: =IFERROR(VLOOKUP(I24,Referensi!$F$5:$G$13,2,FALSE),"") | N24: 12
A25: 21 | B25: Fase 1 | C25: =IFERROR(VLOOKUP(B25,Referensi!$A$5:$B$10,2,FALSE),"") | D25: US-21 | E25: Koreksi metadata manual | F25: User Story | G25: Frontend | H25: Ikhwan | I25: S2 | J25: 3 | K25: Must | L25: To Do | M25: =IFERROR(VLOOKUP(I25,Referensi!$F$5:$G$13,2,FALSE),"") | N25: 13
A26: 22 | B26: Fase 1 | C26: =IFERROR(VLOOKUP(B26,Referensi!$A$5:$B$10,2,FALSE),"") | D26: US-23 | E26: Antrian dokumen gagal & proses ulang | F26: User Story | G26: Backend | H26: Rafli | I26: S2 | J26: 3 | K26: Must | L26: To Do | M26: =IFERROR(VLOOKUP(I26,Referensi!$F$5:$G$13,2,FALSE),"") | N26: 14
A27: 23 | B27: Fase 1 | C27: =IFERROR(VLOOKUP(B27,Referensi!$A$5:$B$10,2,FALSE),"") | D27: US-16 | E27: Baca dokumen dari folder lokal | F27: User Story | G27: Backend | H27: Rafli | I27: S2 | J27: 5 | K27: Must | L27: To Do | M27: =IFERROR(VLOOKUP(I27,Referensi!$F$5:$G$13,2,FALSE),"") | N27: 15
A28: 24 | B28: Fase 1 | C28: =IFERROR(VLOOKUP(B28,Referensi!$A$5:$B$10,2,FALSE),"") | D28: US-24 | E28: Klasifikasi kategori peraturan | F28: User Story | G28: Data/ML | H28: Fathir | I28: S2 | J28: 5 | K28: Must | L28: To Do | M28: =IFERROR(VLOOKUP(I28,Referensi!$F$5:$G$13,2,FALSE),"") | N28: 16
A29: 25 | B29: Fase 1 | C29: =IFERROR(VLOOKUP(B29,Referensi!$A$5:$B$10,2,FALSE),"") | D29: US-25 | E29: Penempatan folder eksisting / baru | F29: User Story | G29: Backend | H29: Rafli | I29: S2 | J29: 5 | K29: Must | L29: To Do | M29: =IFERROR(VLOOKUP(I29,Referensi!$F$5:$G$13,2,FALSE),"") | N29: 17
A30: 26 | B30: Fase 1 | C30: =IFERROR(VLOOKUP(B30,Referensi!$A$5:$B$10,2,FALSE),"") | D30: US-27 | E30: Pencarian dokumen | F30: User Story | G30: Backend | H30: Rafli | I30: S2 | J30: 5 | K30: Must | L30: To Do | M30: =IFERROR(VLOOKUP(I30,Referensi!$F$5:$G$13,2,FALSE),"") | N30: 18
A31: 27 | B31: Fase 1 | C31: =IFERROR(VLOOKUP(B31,Referensi!$A$5:$B$10,2,FALSE),"") | D31: US-28 | E31: Detail dokumen (teks mentah) | F31: User Story | G31: Frontend | H31: Ikhwan | I31: S2 | J31: 3 | K31: Must | L31: To Do | M31: =IFERROR(VLOOKUP(I31,Referensi!$F$5:$G$13,2,FALSE),"") | N31: 19 | O31: Tombol Buka PDF Asli wajib ada
A32: 28 | B32: Fase 1 | C32: =IFERROR(VLOOKUP(B32,Referensi!$A$5:$B$10,2,FALSE),"") | D32: US-32a | E32: Spike: purwarupa parser pasal atas 20 dokumen | F32: Spike | G32: Data/ML | H32: Fathir | I32: S2 | J32: 5 | K32: Must | L32: To Do | M32: =IFERROR(VLOOKUP(I32,Referensi!$F$5:$G$13,2,FALSE),"") | N32: 20 | O32: Butuh 20 dokumen uji dari PM/BA
A33: 29 | B33: Fase 2 | C33: =IFERROR(VLOOKUP(B33,Referensi!$A$5:$B$10,2,FALSE),"") | D33: US-04 | E33: Toggle mode AI-Assisted | F33: User Story | G33: Backend | H33: Rafli | I33: S3 | J33: 5 | K33: Must | L33: To Do | M33: =IFERROR(VLOOKUP(I33,Referensi!$F$5:$G$13,2,FALSE),"")
A34: 30 | B34: Fase 2 | C34: =IFERROR(VLOOKUP(B34,Referensi!$A$5:$B$10,2,FALSE),"") | D34: US-05 | E34: Hasil deterministik & AI tersimpan terpisah | F34: User Story | G34: Backend | H34: Rafli | I34: S3 | J34: 5 | K34: Must | L34: To Do | M34: =IFERROR(VLOOKUP(I34,Referensi!$F$5:$G$13,2,FALSE),"")
A35: 31 | B35: Fase 2 | C35: =IFERROR(VLOOKUP(B35,Referensi!$A$5:$B$10,2,FALSE),"") | D35: US-07 | E35: Label Draft / Rekomendasi pada output | F35: User Story | G35: Frontend | H35: Ikhwan | I35: S3 | J35: 2 | K35: Must | L35: To Do | M35: =IFERROR(VLOOKUP(I35,Referensi!$F$5:$G$13,2,FALSE),"")
A36: 32 | B36: Fase 2 | C36: =IFERROR(VLOOKUP(B36,Referensi!$A$5:$B$10,2,FALSE),"") | D36: US-32 | E36: Parser struktur bab / pasal / ayat | F36: User Story | G36: Data/ML | H36: Fathir | I36: S3 | J36: 13 | K36: Must | L36: To Do | M36: =IFERROR(VLOOKUP(I36,Referensi!$F$5:$G$13,2,FALSE),"") | O36: Jalur kritis — menopang 3 fitur
A37: 33 | B37: Fase 2 | C37: =IFERROR(VLOOKUP(B37,Referensi!$A$5:$B$10,2,FALSE),"") | D37: US-33 | E37: Identifikasi dasar hukum | F37: User Story | G37: Data/ML | H37: Fathir | I37: S3 | J37: 5 | K37: Must | L37: To Do | M37: =IFERROR(VLOOKUP(I37,Referensi!$F$5:$G$13,2,FALSE),"")
A38: 34 | B38: Fase 2 | C38: =IFERROR(VLOOKUP(B38,Referensi!$A$5:$B$10,2,FALSE),"") | D38: US-34 | E38: Identifikasi status keberlakuan | F38: User Story | G38: Data/ML | H38: Fathir | I38: S3 | J38: 5 | K38: Must | L38: To Do | M38: =IFERROR(VLOOKUP(I38,Referensi!$F$5:$G$13,2,FALSE),"")
A39: 35 | B39: Fase 2 | C39: =IFERROR(VLOOKUP(B39,Referensi!$A$5:$B$10,2,FALSE),"") | D39: US-29,30,31 | E39: Versioning, kelola dokumen, status dicabut | F39: User Story | G39: Backend | H39: Rafli | I39: S3 | J39: 11 | K39: Should | L39: To Do | M39: =IFERROR(VLOOKUP(I39,Referensi!$F$5:$G$13,2,FALSE),"") | N39: 37 | O39: Digeser dari Fase 1
A40: 36 | B40: Fase 2 | C40: =IFERROR(VLOOKUP(B40,Referensi!$A$5:$B$10,2,FALSE),"") | D40: US-01 | E40: Manajemen pengguna & peran | F40: User Story | G40: Backend | H40: Rafli | I40: S3 | J40: 5 | K40: Must | L40: To Do | M40: =IFERROR(VLOOKUP(I40,Referensi!$F$5:$G$13,2,FALSE),"") | N40: 32 | O40: Digeser dari Fase 1
A41: 37 | B41: Fase 2 | C41: =IFERROR(VLOOKUP(B41,Referensi!$A$5:$B$10,2,FALSE),"") | D41: US-06 | E41: Fallback saat layanan AI mati | F41: User Story | G41: Backend | H41: Rafli | I41: S4 | J41: 5 | K41: Must | L41: To Do | M41: =IFERROR(VLOOKUP(I41,Referensi!$F$5:$G$13,2,FALSE),"")
...

Sheet Milestone
A1: MILESTONE & INDIKATOR KEBERHASILAN
A2: Indikator per fase sesuai URD mitra. Ubah kolom Status saat ada bukti; isi kolom Bukti dengan tautan atau nomor issue.
A4: Fase | B4: Milestone | C4: Periode | D4: Indikator Keberhasilan | E4: Status | F4: Bukti / Catatan
A5: Fase 0 | B5: Inception & Setup | C5: 31 Aug – 13 Sep 2026 | D5: Dokumen requirement & arsitektur disetujui stakeholder | E5: Sebagian
A6: Fase 0 | B6: Inception & Setup | C6: 31 Aug – 13 Sep 2026 | D6: Infrastruktur dasar (server/storage/repository) siap digunakan | E6: Belum
A7: Fase 0 | B7: Inception & Setup | C7: 31 Aug – 13 Sep 2026 | D7: Struktur folder knowledge base awal (skeleton) tersedia | E7: Belum
A8: Fase 1 | B8: MVP Scraping & Ingest | C8: 14 Sep – 11 Oct 2026 | D8: Berhasil menarik dokumen dari minimal 3 situs sumber yang diinput manual | E8: Belum
A9: Fase 1 | B9: MVP Scraping & Ingest | C9: 14 Sep – 11 Oct 2026 | D9: Fitur unggah manual berfungsi untuk dokumen PDF | E9: Belum
A10: Fase 1 | B10: MVP Scraping & Ingest | C10: 14 Sep – 11 Oct 2026 | D10: Sistem berhasil membaca minimal 1 folder lokal (OneDrive digeser ke Fase 2) | E10: Belum
A11: Fase 1 | B11: MVP Scraping & Ingest | C11: 14 Sep – 11 Oct 2026 | D11: Minimal 20 dokumen peraturan masuk knowledge base (mode Deterministik) | E11: Belum
A12: Fase 1 | B12: MVP Scraping & Ingest | C12: 14 Sep – 11 Oct 2026 | D12: Aplikasi dapat dicoba langsung oleh mitra pada 8 Oktober 2026 | E12: Belum
A13: Fase 2 | B13: MVP Analisa & Summary | C13: 12 Oct – 08 Nov 2026 | D13: Summary & Key Takeaways dihasilkan untuk minimal 10 dokumen uji | E13: Belum
A14: Fase 2 | B14: MVP Analisa & Summary | C14: 12 Oct – 08 Nov 2026 | D14: Waktu proses summary per dokumen di bawah 5 menit pada mode Deterministik | E14: Belum
A15: Fase 2 | B15: MVP Analisa & Summary | C15: 12 Oct – 08 Nov 2026 | D15: Mode AI-Assisted dapat diaktifkan/nonaktifkan dengan narasi lebih natural | E15: Belum
A16: Fase 3 | B16: MVP Harmonisasi | C16: 09 Nov – 29 Nov 2026 | D16: Berhasil membandingkan minimal 5 pasang dokumen (draft vs eksisting) | E16: Belum
... A22: Fase 5 | B22: Stabilisasi & UAT | C22: 14 Dec – 24 Dec 2026 | D22: Sistem berjalan penuh pada mode Deterministik tanpa AI (fallback test) | E22: Belum

Sheet Referensi
A1: REFERENSI
A2: Daftar pilihan dropdown. Ubah di sini bila perlu menambah opsi — seluruh dropdown ikut berubah.
A4: Fase | B4: Milestone | C4: Mulai | D4: Selesai | F4: Sprint | G4: Berakhir | I4: Status | J4: Prioritas | K4: Tipe | L4: Peran | M4: PIC | N4: Status Indikator
A5: Fase 0 | B5: Inception & Setup | C5: 46265 | D5: 46278 | F5: S0 | G5: 46278 | I5: To Do | J5: Must | K5: User Story | L5: PM/BA | M5: Zaky | N5: Belum
A6: Fase 1 | B6: MVP Scraping & Ingest | C6: 46279 | D6: 46306 | F6: S1 | G6: 46292 | I6: In Progress | J6: Should | K6: Spike | L6: Backend | M6: Rafli | N6: Sebagian
A7: Fase 2 | B7: MVP Analisa & Summary | C7: 46307 | D7: 46334 | F7: S2 | G7: 46306 | I7: In Review / Testing | J7: Could | K7: Chore | L7: Frontend | M7: Ikhwan | N7: Tercapai
A8: Fase 3 | B8: MVP Harmonisasi | C8: 46335 | D8: 46355 | F8: S3 | G8: 46320 | I8: Done | J8: Won't | K8: Bug | L8: Data/ML | M8: Fathir
A9: Fase 4 | B9: MVP Tanggapan PoV | C9: 46356 | D9: 46369 | F9: S4 | G9: 46334 | I9: Blocked | K9: Blocker Mitra | L9: Infra/QA | M9: Hamdan
A10: Fase 5 | B10: Stabilisasi & UAT | C10: 46370 | D10: 46380 | F10: S5 | G10: 46348 | L10: Mitra | M10: Faris (DPEA)
F11: S6 | G11: 46362 | M11: Andika (DPEA)
F12: S7 | G12: 46376
F13: S8 | G13: 46380
A17: TIM
A18: Nama | B18: Peran | C18: GitHub | D18: Team Org
A19: Ahmad Zaky Ash Shidqi | B19: PM/BA | C19: cashewwww14 | D19: pm-and-business-analyst
A20: Moh. Rafli Gusti Saputra | B20: Backend | C20: gustiirf | D20: backend
A21: Muhammad Ikhwan | B21: Frontend | C21: Ikhwansantoso | D21: frontend-and-ui-ux
A22: Mirza Syahrizal Fathir | B22: Data/ML | C22: (belum masuk org) | D22: data-and-ml
A23: Ahmad Izzul Hamdan | B23: Infra/QA | C23: Hamdancml | D23: infra-and-qa
A24: Faris Budi | B24: Product Owner (DPEA) | C24: — | D24: —
A25: Andika Wahyu Prihandoko | B25: Mentor (DPEA) | C25: — | D25: —
